Time slot   0
ld_routine
Time slot   1
	Loaded a process at input/proc/p0s, PID: 1 PRIO: 130
	CPU 3: Dispatched process  1
Time slot   2
	Loaded a process at input/proc/s3, PID: 2 PRIO: 39
Time slot   3
liballoc:178
print_pgtbl:
 PDG=b42fb220b390e710 P4g=b42fb220b390e720 PUD=b42fb220b390e730 PMD=b42fb220b390e740
	CPU 2: Dispatched process  2
	CPU 3: Put process  1 to run queue
	CPU 3: Dispatched process  1
liballoc:178
print_pgtbl:
 PDG=b42fb220b390e710 P4g=b42fb220b390e720 PUD=b42fb220b390e730 PMD=b42fb220b390e740
Time slot   4
	Loaded a process at input/proc/m1s, PID: 3 PRIO: 15
libfree:218
print_pgtbl:
 PDG=b42fb220b390e710 P4g=b42fb220b390e720 PUD=b42fb220b390e730 PMD=b42fb220b390e740
Time slot   5
	CPU 2: Put process  2 to run queue
	CPU 2: Dispatched process  3
liballoc:178
print_pgtbl:
 PDG=b42fb220b390ef00 P4g=b42fb220b390ef10 PUD=b42fb220b390ef20 PMD=b42fb220b390ef30
	CPU 1: Dispatched process  2
	CPU 3: Put process  1 to run queue
	CPU 3: Dispatched process  1
liballoc:178
print_pgtbl:
 PDG=b42fb220b390e710 P4g=b42fb220b390e720 PUD=b42fb220b390e730 PMD=b42fb220b390e740
Time slot   6
liballoc:178
print_pgtbl:
 PDG=b42fb220b390ef00 P4g=b42fb220b390ef10 PUD=b42fb220b390ef20 PMD=b42fb220b390ef30
	Loaded a process at input/proc/s2, PID: 4 PRIO: 120
Time slot   7
libwrite:502
print_pgtbl:
 PDG=b42fb220b390e710 P4g=b42fb220b390e720 PUD=b42fb220b390e730 PMD=b42fb220b390e740
	CPU 2: Put process  3 to run queue
	CPU 2: Dispatched process  3
libfree:218
print_pgtbl:
 PDG=b42fb220b390ef00 P4g=b42fb220b390ef10 PUD=b42fb220b390ef20 PMD=b42fb220b390ef30
	CPU 1: Put process  2 to run queue
	CPU 1: Dispatched process  2
	CPU 0: Dispatched process  4
	Loaded a process at input/proc/m0s, PID: 5 PRIO: 120
	CPU 3: Put process  1 to run queue
	CPU 3: Dispatched process  5
liballoc:178
print_pgtbl:
 PDG=b4afc220b391c170 P4g=b4afc220b391c180 PUD=b4afc220b391c190 PMD=b4afc220b391c1a0
Time slot   8
liballoc:178
print_pgtbl:
 PDG=b42fb220b390ef00 P4g=b42fb220b390ef10 PUD=b42fb220b390ef20 PMD=b42fb220b390ef30
liballoc:178
print_pgtbl:
 PDG=b4afc220b391c170 P4g=b4afc220b391c180 PUD=b4afc220b391c190 PMD=b4afc220b391c1a0
Time slot   9
	CPU 2: Put process  3 to run queue
	CPU 2: Dispatched process  3
libfree:218
print_pgtbl:
 PDG=b42fb220b390ef00 P4g=b42fb220b390ef10 PUD=b42fb220b390ef20 PMD=b42fb220b390ef30
	CPU 1: Put process  2 to run queue
	CPU 1: Dispatched process  2
	CPU 0: Put process  4 to run queue
	CPU 0: Dispatched process  4
	Loaded a process at input/proc/p1s, PID: 6 PRIO: 15
	CPU 3: Put process  5 to run queue
	CPU 3: Dispatched process  6
Time slot  10
libfree:218
print_pgtbl:
 PDG=b42fb220b390ef00 P4g=b42fb220b390ef10 PUD=b42fb220b390ef20 PMD=b42fb220b390ef30
Time slot  11
	CPU 2: Processed  3 has finished
	CPU 2: Dispatched process  5
libfree:218
print_pgtbl:
 PDG=b4afc220b391c170 P4g=b4afc220b391c180 PUD=b4afc220b391c190 PMD=b4afc220b391c1a0
	CPU 1: Put process  2 to run queue
	CPU 1: Dispatched process  2
	CPU 0: Put process  4 to run queue
	CPU 0: Dispatched process  4
	Loaded a process at input/proc/s0, PID: 7 PRIO: 38
	CPU 3: Put process  6 to run queue
	CPU 3: Dispatched process  6
Time slot  12
liballoc:178
print_pgtbl:
 PDG=b4afc220b391c170 P4g=b4afc220b391c180 PUD=b4afc220b391c190 PMD=b4afc220b391c1a0
	CPU 2: Put process  5 to run queue
	CPU 2: Dispatched process  7
Time slot  13
	CPU 1: Put process  2 to run queue
	CPU 1: Dispatched process  2
	CPU 0: Put process  4 to run queue
	CPU 0: Dispatched process  5
libwrite:502
print_pgtbl:
 PDG=b4afc220b391c170 P4g=b4afc220b391c180 PUD=b4afc220b391c190 PMD=b4afc220b391c1a0
	CPU 3: Put process  6 to run queue
	CPU 3: Dispatched process  6
Time slot  14
	CPU 1: Processed  2 has finished
	CPU 1: Dispatched process  4
libwrite:502
print_pgtbl:
 PDG=b4afc220b391c170 P4g=b4afc220b391c180 PUD=b4afc220b391c190 PMD=b4afc220b391c1a0
	CPU 2: Put process  7 to run queue
	CPU 2: Dispatched process  7
Time slot  15
	CPU 0: Processed  5 has finished
	CPU 0: Dispatched process  1
libread:426
print_pgtbl:
 PDG=b42fb220b390e710 P4g=b42fb220b390e720 PUD=b42fb220b390e730 PMD=b42fb220b390e740
	CPU 3: Put process  6 to run queue
	CPU 3: Dispatched process  6
Time slot  16
	CPU 1: Put process  4 to run queue
	CPU 1: Dispatched process  4
libwrite:502
print_pgtbl:
 PDG=b42fb220b390e710 P4g=b42fb220b390e720 PUD=b42fb220b390e730 PMD=b42fb220b390e740
	Loaded a process at input/proc/s1, PID: 8 PRIO: 0
	CPU 2: Put process  7 to run queue
	CPU 2: Dispatched process  8
Time slot  17
	CPU 0: Put process  1 to run queue
	CPU 0: Dispatched process  7
	CPU 3: Put process  6 to run queue
	CPU 3: Dispatched process  6
Time slot  18
	CPU 1: Put process  4 to run queue
	CPU 1: Dispatched process  4
	CPU 2: Put process  8 to run queue
	CPU 2: Dispatched process  8
Time slot  19
	CPU 0: Put process  7 to run queue
	CPU 0: Dispatched process  7
	CPU 3: Processed  6 has finished
	CPU 3: Dispatched process  1
libread:426
print_pgtbl:
 PDG=b42fb220b390e710 P4g=b42fb220b390e720 PUD=b42fb220b390e730 PMD=b42fb220b390e740
Time slot  20
	CPU 1: Processed  4 has finished
	CPU 1 stopped
libwrite:502
print_pgtbl:
 PDG=b42fb220b390e710 P4g=b42fb220b390e720 PUD=b42fb220b390e730 PMD=b42fb220b390e740
	CPU 2: Put process  8 to run queue
	CPU 2: Dispatched process  8
	CPU 0: Put process  7 to run queue
Time slot  21
	CPU 0: Dispatched process  7
	CPU 3: Put process  1 to run queue
	CPU 3: Dispatched process  1
Time slot  22
libread:426
print_pgtbl:
 PDG=b42fb220b390e710 P4g=b42fb220b390e720 PUD=b42fb220b390e730 PMD=b42fb220b390e740
	CPU 2: Put process  8 to run queue
Time slot  23
	CPU 2: Dispatched process  8
	CPU 0: Put process  7 to run queue
	CPU 0: Dispatched process  7
	CPU 3: Put process  1 to run queue
Time slot  24
	CPU 3: Dispatched process  1
libfree:218
print_pgtbl:
 PDG=b42fb220b390e710 P4g=b42fb220b390e720 PUD=b42fb220b390e730 PMD=b42fb220b390e740
	CPU 2: Processed  8 has finished
	CPU 2 stopped
Time slot  25
	CPU 0: Put process  7 to run queue
	CPU 0: Dispatched process  7
Time slot  26
	CPU 3: Processed  1 has finished
	CPU 3 stopped
Time slot  27
	CPU 0: Put process  7 to run queue
	CPU 0: Dispatched process  7
Time slot  28
	CPU 0: Processed  7 has finished
	CPU 0 stopped
