Time slot   0
ld_routine
Time slot   1
	Loaded a process at input/proc/p0s, PID: 1 PRIO: 130
Time slot   2
	CPU 1: Dispatched process  1
	Loaded a process at input/proc/s3, PID: 2 PRIO: 39
Time slot   3
liballoc:178
print_pgtbl:
 PDG=b52fd220b490e6f0 P4g=b52fd220b490e700 PUD=b52fd220b490e710 PMD=b52fd220b490e720
	CPU 2: Dispatched process  2
Time slot   4
	CPU 1: Put process  1 to run queue
	CPU 1: Dispatched process  1
liballoc:178
print_pgtbl:
 PDG=b52fd220b490e6f0 P4g=b52fd220b490e700 PUD=b52fd220b490e710 PMD=b52fd220b490e720
	Loaded a process at input/proc/m1s, PID: 3 PRIO: 15
	CPU 3: Dispatched process  3
liballoc:178
print_pgtbl:
 PDG=b52fd220b491a6f0 P4g=b52fd220b491a700 PUD=b52fd220b491a710 PMD=b52fd220b491a720
	CPU 2: Put process  2 to run queue
	CPU 2: Dispatched process  2
Time slot   5
libfree:218
print_pgtbl:
 PDG=b52fd220b490e6f0 P4g=b52fd220b490e700 PUD=b52fd220b490e710 PMD=b52fd220b490e720
Time slot   6
liballoc:178
print_pgtbl:
 PDG=b52fd220b491a6f0 P4g=b52fd220b491a700 PUD=b52fd220b491a710 PMD=b52fd220b491a720
	CPU 1: Put process  1 to run queue
	CPU 1: Dispatched process  1
liballoc:178
print_pgtbl:
 PDG=b52fd220b490e6f0 P4g=b52fd220b490e700 PUD=b52fd220b490e710 PMD=b52fd220b490e720
	Loaded a process at input/proc/s2, PID: 4 PRIO: 120
Time slot   7
	CPU 3: Put process  3 to run queue
	CPU 3: Dispatched process  3
	CPU 2: Put process  2 to run queue
	CPU 2: Dispatched process  2
	CPU 0: Dispatched process  4
libwrite:502
print_pgtbl:
 PDG=b52fd220b490e6f0 P4g=b52fd220b490e700 PUD=b52fd220b490e710 PMD=b52fd220b490e720
	Loaded a process at input/proc/m0s, PID: 5 PRIO: 120
Time slot   8
liballoc:178
print_pgtbl:
 PDG=b52fd220b491a6f0 P4g=b52fd220b491a700 PUD=b52fd220b491a710 PMD=b52fd220b491a720
	CPU 1: Put process  1 to run queue
	CPU 1: Dispatched process  5
liballoc:178
print_pgtbl:
 PDG=b52fd220b49266f0 P4g=b52fd220b4926700 PUD=b52fd220b4926710 PMD=b52fd220b4926720
Time slot   9
	CPU 3: Put process  3 to run queue
	CPU 3: Dispatched process  1
libread:426
print_pgtbl:
 PDG=b52fd220b490e6f0 P4g=b52fd220b490e700 PUD=b52fd220b490e710 PMD=b52fd220b490e720
	CPU 2: Put process  2 to run queue
	CPU 2: Dispatched process  3
libfree:218
print_pgtbl:
 PDG=b52fd220b491a6f0 P4g=b52fd220b491a700 PUD=b52fd220b491a710 PMD=b52fd220b491a720
	CPU 0: Put process  4 to run queue
	CPU 0: Dispatched process  2
liballoc:178
print_pgtbl:
 PDG=b52fd220b49266f0 P4g=b52fd220b4926700 PUD=b52fd220b4926710 PMD=b52fd220b4926720
	Loaded a process at input/proc/p1s, PID: 6 PRIO: 15
Time slot  10
	CPU 1: Put process  5 to run queue
	CPU 1: Dispatched process  4
libwrite:502
print_pgtbl:
 PDG=b52fd220b490e6f0 P4g=b52fd220b490e700 PUD=b52fd220b490e710 PMD=b52fd220b490e720
Time slot  11
	CPU 3: Put process  1 to run queue
	CPU 0: Put process  2 to run queue
	CPU 0: Dispatched process  5
	CPU 2: Processed  3 has finished
	CPU 3: Dispatched process  1
libread:426
print_pgtbl:
 PDG=b52fd220b490e6f0 P4g=b52fd220b490e700 PUD=b52fd220b490e710 PMD=b52fd220b490e720
	Loaded a process at input/proc/s0, PID: 7 PRIO: 38
	CPU 2: Dispatched process  6
libwrite:502
print_pgtbl:
 PDG=b52fd220b490e6f0 P4g=b52fd220b490e700 PUD=b52fd220b490e710 PMD=b52fd220b490e720
	CPU 1: Put process  4 to run queue
	CPU 1: Dispatched process  7
Time slot  12
liballoc:178
print_pgtbl:
 PDG=b52fd220b49266f0 P4g=b52fd220b4926700 PUD=b52fd220b4926710 PMD=b52fd220b4926720
Time slot  13
	CPU 3: Put process  1 to run queue
	CPU 3: Dispatched process  2
	CPU 2: Put process  6 to run queue
	CPU 2: Dispatched process  4
	CPU 0: Put process  5 to run queue
	CPU 0: Dispatched process  5
libwrite:502
print_pgtbl:
 PDG=b52fd220b49266f0 P4g=b52fd220b4926700 PUD=b52fd220b4926710 PMD=b52fd220b4926720
Time slot  14
	CPU 1: Put process  7 to run queue
	CPU 1: Dispatched process  1
libread:426
print_pgtbl:
 PDG=b52fd220b490e6f0 P4g=b52fd220b490e700 PUD=b52fd220b490e710 PMD=b52fd220b490e720
libwrite:502
print_pgtbl:
 PDG=b52fd220b49266f0 P4g=b52fd220b4926700 PUD=b52fd220b4926710 PMD=b52fd220b4926720
	CPU 2: Put process  4 to run queue
	CPU 3: Put process  2 to run queue
	CPU 3: Dispatched process  6
	CPU 2: Dispatched process  7
	CPU 0: Processed  5 has finished
	CPU 0: Dispatched process  2
Time slot  15
Time slot  16
	CPU 1: Put process  1 to run queue
	CPU 1: Dispatched process  4
	CPU 0: Processed  2 has finished
	CPU 0: Dispatched process  1
	Loaded a process at input/proc/s1, PID: 8 PRIO: 0
Time slot  17
	CPU 3: Put process  6 to run queue
	CPU 3: Dispatched process  8
	CPU 2: Put process  7 to run queue
	CPU 2: Dispatched process  6
Time slot  18
	CPU 1: Put process  4 to run queue
	CPU 0: Processed  1 has finished
	CPU 1: Dispatched process  7
	CPU 0: Dispatched process  4
	CPU 3: Put process  8 to run queue
Time slot  19
	CPU 3: Dispatched process  8
	CPU 2: Put process  6 to run queue
	CPU 2: Dispatched process  6
Time slot  20
	CPU 1: Put process  7 to run queue
	CPU 1: Dispatched process  7
	CPU 0: Put process  4 to run queue
	CPU 0: Dispatched process  4
	CPU 3: Put process  8 to run queue
	CPU 3: Dispatched process  8
Time slot  21
	CPU 2: Put process  6 to run queue
	CPU 2: Dispatched process  6
Time slot  22
	CPU 1: Put process  7 to run queue
	CPU 1: Dispatched process  7
	CPU 0: Processed  4 has finished
	CPU 0 stopped
	CPU 3: Put process  8 to run queue
Time slot  23
	CPU 3: Dispatched process  8
	CPU 2: Processed  6 has finished
	CPU 2 stopped
Time slot  24
	CPU 3: Processed  8 has finished
	CPU 1: Put process  7 to run queue
	CPU 3 stopped
	CPU 1: Dispatched process  7
Time slot  25
Time slot  26
	CPU 1: Put process  7 to run queue
	CPU 1: Dispatched process  7
Time slot  27
Time slot  28
	CPU 1: Put process  7 to run queue
	CPU 1: Dispatched process  7
Time slot  29
	CPU 1: Processed  7 has finished
	CPU 1 stopped
